<?xml version="1.0" ?>
<!-- =================================================================================== -->
<!-- |    This document was autogenerated by xacro from /home/spaceassembly/iiwa_ws/src/iiwa_package-main/iiwa_cam/src/urdf/pink_iiwa.xacro | -->
<!-- |    EDITING THIS FILE BY HAND IS NOT RECOMMENDED                                 | -->
<!-- =================================================================================== -->
<robot name="global workspace">
    <link name="world" />
    <!-- KUKA -->
    <material name="Black">
        <color rgba="0.0 0.0 0.0 1.0" />
    </material>
    <material name="Blue">
        <color rgba="0.0 0.0 0.8 1.0" />
    </material>
    <material name="Green">
        <color rgba="0.0 0.8 0.0 1.0" />
    </material>
    <material name="Grey">
        <color rgba="0.4 0.4 0.4 1.0" />
    </material>
    <material name="Orange">
        <color rgba="1.0 0.4235294117647059 0.0392156862745098 1.0" />
    </material>
    <material name="Brown">
        <color rgba="0.8705882352941177 0.8117647058823529 0.7647058823529411 1.0" />
    </material>
    <material name="Red">
        <color rgba="0.8 0.0 0.0 1.0" />
    </material>
    <material name="White">
        <color rgba="1.0 1.0 1.0 1.0" />
    </material>
    <!-- <xacro:include filename="$(find iiwa_cam)/src/urdf/gripper_assembly.xacro"/> -->
    <!-- <xacro:arg name="robot_name_2" default="iiwa_blue" /> -->
    <!--joint between {parent} and link_0-->
    <joint name="world_iiwa_pink_joint" type="fixed">
        <origin rpy="0 0 1.5708" xyz="0 0 0" />
        <parent link="world" />
        <child link="iiwa_pink_link_0" />
    </joint>
    <link name="iiwa_pink_link_0">
        <inertial>
            <origin rpy="0 0 0" xyz="-0.1 0 0.07" />
            <mass value="5" />
            <inertia ixx="0.05" ixy="0" ixz="0" iyy="0.06" iyz="0" izz="0.03" />
        </inertial>
        <visual>
            <origin rpy="0 0 0" xyz="0 0 0" />
            <geometry>
                <mesh filename="package://iiwa_description/meshes/iiwa14/visual/link_0.stl" />
            </geometry>
            <material name="Grey" />
        </visual>
        <collision>
            <origin rpy="0 0 0" xyz="0 0 0" />
            <geometry>
                <mesh filename="package://iiwa_description/meshes/iiwa14/collision/link_0.stl" />
            </geometry>
            <material name="Grey" />
        </collision>
        <self_collision_checking>
            <origin rpy="0 0 0" xyz="0 0 0" />
            <geometry>
                <capsule length="0.25" radius="0.15" />
            </geometry>
        </self_collision_checking>
    </link>
    <!-- joint between link_0 and link_1 -->
    <joint name="iiwa_pink_joint_1" type="revolute">
        <parent link="iiwa_pink_link_0" />
        <child link="iiwa_pink_link_1" />
        <origin rpy="0 0 0" xyz="0 0 0.1575" />
        <axis xyz="0 0 1" />
        <limit effort="300" lower="-2.9670597283903604" upper="2.9670597283903604" velocity="10" />
        <safety_controller k_position="100" k_velocity="2" soft_lower_limit="-2.9321531433504737" soft_upper_limit="2.9321531433504737" />
        <dynamics damping="0.5" />
    </joint>
    <link name="iiwa_pink_link_1">
        <inertial>
            <origin rpy="0 0 0" xyz="0 -0.03 0.12" />
            <mass value="4" />
            <inertia ixx="0.1" ixy="0" ixz="0" iyy="0.09" iyz="0" izz="0.02" />
        </inertial>
        <visual>
            <origin rpy="0 0 0" xyz="0 0 0" />
            <geometry>
                <mesh filename="package://iiwa_description/meshes/iiwa14/visual/link_1.stl" />
            </geometry>
            <material name="Orange" />
        </visual>
        <collision>
            <origin rpy="0 0 0" xyz="0 0 0" />
            <geometry>
                <mesh filename="package://iiwa_description/meshes/iiwa14/collision/link_1.stl" />
            </geometry>
            <material name="Orange" />
        </collision>
    </link>
    <!-- joint between link_1 and link_2 -->
    <joint name="iiwa_pink_joint_2" type="revolute">
        <parent link="iiwa_pink_link_1" />
        <child link="iiwa_pink_link_2" />
        <origin rpy="1.5707963267948966   0 3.141592653589793" xyz="0 0 0.2025" />
        <axis xyz="0 0 1" />
        <limit effort="300" lower="-2.0943951023931953" upper="2.0943951023931953" velocity="10" />
        <safety_controller k_position="100" k_velocity="2" soft_lower_limit="-2.0594885173533086" soft_upper_limit="2.0594885173533086" />
        <dynamics damping="0.5" />
    </joint>
    <link name="iiwa_pink_link_2">
        <inertial>
            <origin rpy="0 0 0" xyz="0.0003 0.059 0.042" />
            <mass value="4" />
            <inertia ixx="0.05" ixy="0" ixz="0" iyy="0.018" iyz="0" izz="0.044" />
        </inertial>
        <visual>
            <origin rpy="0 0 0" xyz="0 0 0" />
            <geometry>
                <mesh filename="package://iiwa_description/meshes/iiwa14/visual/link_2.stl" />
            </geometry>
            <material name="Orange" />
        </visual>
        <collision>
            <origin rpy="0 0 0" xyz="0 0 0" />
            <geometry>
                <mesh filename="package://iiwa_description/meshes/iiwa14/collision/link_2.stl" />
            </geometry>
            <material name="Orange" />
        </collision>
    </link>
    <!-- joint between link_2 and link_3 -->
    <joint name="iiwa_pink_joint_3" type="revolute">
        <parent link="iiwa_pink_link_2" />
        <child link="iiwa_pink_link_3" />
        <origin rpy="1.5707963267948966 0 3.141592653589793" xyz="0 0.2045 0" />
        <axis xyz="0 0 1" />
        <limit effort="300" lower="-2.9670597283903604" upper="2.9670597283903604" velocity="10" />
        <safety_controller k_position="100" k_velocity="2" soft_lower_limit="-2.9321531433504737" soft_upper_limit="2.9321531433504737" />
        <dynamics damping="0.5" />
    </joint>
    <link name="iiwa_pink_link_3">
        <inertial>
            <origin rpy="0 0 0" xyz="0 0.03 0.13" />
            <mass value="3" />
            <inertia ixx="0.08" ixy="0" ixz="0" iyy="0.075" iyz="0" izz="0.01" />
        </inertial>
        <visual>
            <origin rpy="0 0 0" xyz="0 0 0" />
            <geometry>
                <mesh filename="package://iiwa_description/meshes/iiwa14/visual/link_3.stl" />
            </geometry>
            <material name="Orange" />
        </visual>
        <collision>
            <origin rpy="0 0 0" xyz="0 0 0" />
            <geometry>
                <mesh filename="package://iiwa_description/meshes/iiwa14/collision/link_3.stl" />
            </geometry>
            <material name="Orange" />
        </collision>
    </link>
    <!-- joint between link_3 and link_4 -->
    <joint name="iiwa_pink_joint_4" type="revolute">
        <parent link="iiwa_pink_link_3" />
        <child link="iiwa_pink_link_4" />
        <origin rpy="1.5707963267948966 0 0" xyz="0 0 0.2155" />
        <axis xyz="0 0 1" />
        <limit effort="300" lower="-2.0943951023931953" upper="2.0943951023931953" velocity="10" />
        <safety_controller k_position="100" k_velocity="2" soft_lower_limit="-2.0594885173533086" soft_upper_limit="2.0594885173533086" />
        <dynamics damping="0.5" />
    </joint>
    <link name="iiwa_pink_link_4">
        <inertial>
            <origin rpy="0 0 0" xyz="0 0.067 0.034" />
            <mass value="2.7" />
            <inertia ixx="0.03" ixy="0" ixz="0" iyy="0.01" iyz="0" izz="0.029" />
        </inertial>
        <visual>
            <origin rpy="0 0 0" xyz="0 0 0" />
            <geometry>
                <mesh filename="package://iiwa_description/meshes/iiwa14/visual/link_4.stl" />
            </geometry>
            <material name="Orange" />
        </visual>
        <collision>
            <origin rpy="0 0 0" xyz="0 0 0" />
            <geometry>
                <mesh filename="package://iiwa_description/meshes/iiwa14/collision/link_4.stl" />
            </geometry>
            <material name="Orange" />
        </collision>
    </link>
    <!-- joint between link_4 and link_5 -->
    <joint name="iiwa_pink_joint_5" type="revolute">
        <parent link="iiwa_pink_link_4" />
        <child link="iiwa_pink_link_5" />
        <origin rpy="-1.5707963267948966 3.141592653589793 0" xyz="0 0.1845 0" />
        <axis xyz="0 0 1" />
        <limit effort="300" lower="-2.9670597283903604" upper="2.9670597283903604" velocity="10" />
        <safety_controller k_position="100" k_velocity="2" soft_lower_limit="-2.9321531433504737" soft_upper_limit="2.9321531433504737" />
        <dynamics damping="0.5" />
    </joint>
    <link name="iiwa_pink_link_5">
        <inertial>
            <origin rpy="0 0 0" xyz="0.0001 0.021 0.076" />
            <mass value="1.7" />
            <inertia ixx="0.02" ixy="0" ixz="0" iyy="0.018" iyz="0" izz="0.005" />
        </inertial>
        <visual>
            <origin rpy="0 0 0" xyz="0 0 0" />
            <geometry>
                <mesh filename="package://iiwa_description/meshes/iiwa14/visual/link_5.stl" />
            </geometry>
            <material name="Orange" />
        </visual>
        <collision>
            <origin rpy="0 0 0" xyz="0 0 0" />
            <geometry>
                <mesh filename="package://iiwa_description/meshes/iiwa14/collision/link_5.stl" />
            </geometry>
            <material name="Orange" />
        </collision>
    </link>
    <!-- joint between link_5 and link_6 -->
    <joint name="iiwa_pink_joint_6" type="revolute">
        <parent link="iiwa_pink_link_5" />
        <child link="iiwa_pink_link_6" />
        <origin rpy="1.5707963267948966 0 0" xyz="0 0 0.2155" />
        <axis xyz="0 0 1" />
        <limit effort="300" lower="-2.0943951023931953" upper="2.0943951023931953" velocity="10" />
        <safety_controller k_position="100" k_velocity="2" soft_lower_limit="-2.0594885173533086" soft_upper_limit="2.0594885173533086" />
        <dynamics damping="0.5" />
    </joint>
    <link name="iiwa_pink_link_6">
        <inertial>
            <origin rpy="0 0 0" xyz="0 0.0006 0.0004" />
            <mass value="1.8" />
            <inertia ixx="0.005" ixy="0" ixz="0" iyy="0.0036" iyz="0" izz="0.0047" />
        </inertial>
        <visual>
            <origin rpy="0 0 0" xyz="0 0 0" />
            <geometry>
                <mesh filename="package://iiwa_description/meshes/iiwa14/visual/link_6.stl" />
            </geometry>
            <material name="Orange" />
        </visual>
        <collision>
            <origin rpy="0 0 0" xyz="0 0 0" />
            <geometry>
                <mesh filename="package://iiwa_description/meshes/iiwa14/collision/link_6.stl" />
            </geometry>
            <material name="Orange" />
        </collision>
    </link>
    <!-- joint between link_6 and link_7 -->
    <joint name="iiwa_pink_joint_7" type="revolute">
        <parent link="iiwa_pink_link_6" />
        <child link="iiwa_pink_link_7" />
        <origin rpy="-1.5707963267948966 3.141592653589793 0" xyz="0 0.081 0" />
        <axis xyz="0 0 1" />
        <limit effort="300" lower="-3.0543261909900763" upper="3.0543261909900763" velocity="10" />
        <safety_controller k_position="100" k_velocity="2" soft_lower_limit="-3.01941960595019" soft_upper_limit="3.01941960595019" />
        <dynamics damping="0.5" />
    </joint>
    <link name="iiwa_pink_link_7">
        <inertial>
            <origin rpy="0 0 0" xyz="0 0 0.02" />
            <mass value="0.3" />
            <inertia ixx="0.001" ixy="0" ixz="0" iyy="0.001" iyz="0" izz="0.001" />
        </inertial>
        <visual>
            <origin rpy="0 0 0" xyz="0 0 0" />
            <geometry>
                <mesh filename="package://iiwa_description/meshes/iiwa14/visual/link_7.stl" />
            </geometry>
            <material name="Grey" />
        </visual>
        <collision>
            <origin rpy="0 0 0" xyz="0 0 0" />
            <geometry>
                <mesh filename="package://iiwa_description/meshes/iiwa14/collision/link_7.stl" />
            </geometry>
            <material name="Grey" />
        </collision>
    </link>
    <!-- joint between link_7 and link_ee -->
    <joint name="iiwa_pink_joint_ee" type="fixed">
        <parent link="iiwa_pink_link_7" />
        <child link="iiwa_pink_link_ee" />
        <origin rpy="0 0 0" xyz="0 0 0.045" />
    </joint>
    <link name="iiwa_pink_link_ee">
        <!-- Define the visual properties of the object -->
        <visual>
            <origin rpy="0 0 0" xyz="0 0 0" />
            <geometry>
                <!-- Specify the mesh file or other geometry representation -->
                <!-- For example, using a mesh file -->
                <mesh filename="package://iiwa_description/meshes/space_assembly/visual/space_ee.stl" />
            </geometry>
            <material name="White" />
        </visual>
        <!-- Define the collision properties of the object -->
        <collision>
            <origin rpy="0 0 0" xyz="0 0 0" />
            <geometry>
                <!-- Specify the mesh file or other geometry representation -->
                <!-- For example, using a mesh file -->
                <mesh filename="package://iiwa_description/meshes/space_assembly/visual/space_ee.stl" />
            </geometry>
            <material name="White" />
        </collision>
        <inertial>
            <mass value="0.1" />
            <origin xyz="0 0 0" rpy="0 0 0" />
            <inertia ixx="0.03" iyy="0.03" izz="0.03" ixy="0.0" ixz="0.0" iyz="0.0" />
        </inertial>
    </link>
    <!-- <joint name="${parent}_${robot_name}_fixed_object_joint" type="fixed">
      <xacro:insert_block name="origin"/>
      <parent link="${parent}"/>
      <child link="${robot_name}_fixed_object"/>
    </joint> -->
    <!-- <link name="${robot_name}_fixed_object"> -->
    <!-- Define the visual properties of the object -->
    <!-- <visual> -->
    <!-- <origin xyz="1 0 0" rpy="0 0 0"/> -->
    <!-- <geometry> -->
    <!-- Specify the mesh file or other geometry representation -->
    <!-- For example, using a mesh file -->
    <!-- <mesh filename="package://iiwa_description/meshes/space_assembly/visual/space_assembly.stl" scale=".001 .001 .001"/> -->
    <!-- <mesh filename="package://iiwa_description/meshes/space_assembly/visual/space_assembly.stl"/> -->
    <!-- </geometry> -->
    <!-- <material name="White"/> -->
    <!-- </visual> -->
    <!-- Define the collision properties of the object -->
    <!-- <collision> -->
    <!-- <origin xyz="1 0 0" rpy="0 0 0"/> -->
    <!-- <geometry> -->
    <!-- Specify the mesh file or other geometry representation -->
    <!-- For example, using a mesh file -->
    <!-- <mesh filename="package://iiwa_description/meshes/space_assembly/collision/space_assembly.stl" scale=".001 .001 .001"/> -->
    <!-- <mesh filename="package://iiwa_description/meshes/space_assembly/visual/space_assembly.stl"/> -->
    <!-- </geometry> -->
    <!-- <material name="White"/> -->
    <!-- </collision> -->
    <!-- </link> -->
    <!-- Enable the Joint Feedback -->
    <gazebo reference="iiwa_pink_joint_7">
        <provideFeedback>true</provideFeedback>
        <plugin name="gazebo_ros_control">
            <robotNamespace>/</robotNamespace>
        </plugin>
    </gazebo>
    <!-- The ft_sensor plugin -->
    <gazebo>
        <plugin filename="libgazebo_ros_ft_sensor.so" name="ft_sensor">
            <updateRate>50.0</updateRate>
            <topicName>/iiwa_pink/state/CartesianWrench</topicName>
            <jointName>iiwa_pink_joint_7</jointName>
        </plugin>
    </gazebo>
    <!-- Load Gazebo lib and set the robot namespace -->
    <gazebo>
        <plugin filename="libgazebo_ros_control.so" name="gazebo_ros_control">
            <robotNamespace>/iiwa_pink</robotNamespace>
        </plugin>
    </gazebo>
    <!-- Link0 -->
    <gazebo reference="iiwa_pink_link_0">
        <material>Gazebo/Grey</material>
        <mu1>0.2</mu1>
        <mu2>0.2</mu2>
    </gazebo>
    <!-- Link1 -->
    <gazebo reference="iiwa_pink_link_1">
        <material>Gazebo/Orange</material>
        <mu1>0.2</mu1>
        <mu2>0.2</mu2>
    </gazebo>
    <!-- Link2 -->
    <gazebo reference="iiwa_pink_link_2">
        <material>Gazebo/Orange</material>
        <mu1>0.2</mu1>
        <mu2>0.2</mu2>
    </gazebo>
    <!-- Link3 -->
    <gazebo reference="iiwa_pink_link_3">
        <material>Gazebo/Orange</material>
        <mu1>0.2</mu1>
        <mu2>0.2</mu2>
    </gazebo>
    <!-- Link4 -->
    <gazebo reference="iiwa_pink_link_4">
        <material>Gazebo/Orange</material>
        <mu1>0.2</mu1>
        <mu2>0.2</mu2>
    </gazebo>
    <!-- Link5 -->
    <gazebo reference="iiwa_pink_link_5">
        <material>Gazebo/Orange</material>
        <mu1>0.2</mu1>
        <mu2>0.2</mu2>
    </gazebo>
    <!-- Link6 -->
    <gazebo reference="iiwa_pink_link_6">
        <material>Gazebo/Orange</material>
        <mu1>0.2</mu1>
        <mu2>0.2</mu2>
    </gazebo>
    <!-- Link7 -->
    <gazebo reference="iiwa_pink_link_7">
        <material>Gazebo/Grey</material>
        <mu1>0.2</mu1>
        <mu2>0.2</mu2>
    </gazebo>
    <transmission name="iiwa_pink_tran_1">
        <robotNamespace>/iiwa_pink</robotNamespace>
        <type>transmission_interface/SimpleTransmission</type>
        <joint name="iiwa_pink_joint_1">
            <hardwareInterface>hardware_interface/PositionJointInterface</hardwareInterface>
        </joint>
        <actuator name="iiwa_pink_motor_1">
            <hardwareInterface>hardware_interface/PositionJointInterface</hardwareInterface>
            <mechanicalReduction>1</mechanicalReduction>
        </actuator>
    </transmission>
    <transmission name="iiwa_pink_tran_2">
        <robotNamespace>/iiwa_pink</robotNamespace>
        <type>transmission_interface/SimpleTransmission</type>
        <joint name="iiwa_pink_joint_2">
            <hardwareInterface>hardware_interface/PositionJointInterface</hardwareInterface>
        </joint>
        <actuator name="iiwa_pink_motor_2">
            <hardwareInterface>hardware_interface/PositionJointInterface</hardwareInterface>
            <mechanicalReduction>1</mechanicalReduction>
        </actuator>
    </transmission>
    <transmission name="iiwa_pink_tran_3">
        <robotNamespace>/iiwa_pink</robotNamespace>
        <type>transmission_interface/SimpleTransmission</type>
        <joint name="iiwa_pink_joint_3">
            <hardwareInterface>hardware_interface/PositionJointInterface</hardwareInterface>
        </joint>
        <actuator name="iiwa_pink_motor_3">
            <hardwareInterface>hardware_interface/PositionJointInterface</hardwareInterface>
            <mechanicalReduction>1</mechanicalReduction>
        </actuator>
    </transmission>
    <transmission name="iiwa_pink_tran_4">
        <robotNamespace>/iiwa_pink</robotNamespace>
        <type>transmission_interface/SimpleTransmission</type>
        <joint name="iiwa_pink_joint_4">
            <hardwareInterface>hardware_interface/PositionJointInterface</hardwareInterface>
        </joint>
        <actuator name="iiwa_pink_motor_4">
            <hardwareInterface>hardware_interface/PositionJointInterface</hardwareInterface>
            <mechanicalReduction>1</mechanicalReduction>
        </actuator>
    </transmission>
    <transmission name="iiwa_pink_tran_5">
        <robotNamespace>/iiwa_pink</robotNamespace>
        <type>transmission_interface/SimpleTransmission</type>
        <joint name="iiwa_pink_joint_5">
            <hardwareInterface>hardware_interface/PositionJointInterface</hardwareInterface>
        </joint>
        <actuator name="iiwa_pink_motor_5">
            <hardwareInterface>hardware_interface/PositionJointInterface</hardwareInterface>
            <mechanicalReduction>1</mechanicalReduction>
        </actuator>
    </transmission>
    <transmission name="iiwa_pink_tran_6">
        <robotNamespace>/iiwa_pink</robotNamespace>
        <type>transmission_interface/SimpleTransmission</type>
        <joint name="iiwa_pink_joint_6">
            <hardwareInterface>hardware_interface/PositionJointInterface</hardwareInterface>
        </joint>
        <actuator name="iiwa_pink_motor_6">
            <hardwareInterface>hardware_interface/PositionJointInterface</hardwareInterface>
            <mechanicalReduction>1</mechanicalReduction>
        </actuator>
    </transmission>
    <transmission name="iiwa_pink_tran_7">
        <robotNamespace>/iiwa_pink</robotNamespace>
        <type>transmission_interface/SimpleTransmission</type>
        <joint name="iiwa_pink_joint_7">
            <hardwareInterface>hardware_interface/PositionJointInterface</hardwareInterface>
        </joint>
        <actuator name="iiwa_pink_motor_7">
            <hardwareInterface>hardware_interface/PositionJointInterface</hardwareInterface>
            <mechanicalReduction>1</mechanicalReduction>
        </actuator>
    </transmission>
    <joint name="iiwa_pink_space_assembly_joint" type="fixed">
        <parent link="world" />
        <child link="iiwa_pink_space_assembly" />
        <!-- <origin xyz="-0.1015 0.05 0" rpy="0 0 0" />  Might need to fix this-->
    </joint>
    <link name="iiwa_pink_space_assembly">
        <!-- <inertial>
                <origin xyz="1 0 0 " rpy="0 0 0" />
                <mass value="1" />
                <inertia ixx="0.04010" ixy="0" ixz="0" iyy="0.03365" iyz="0" izz="0.0427" />
            </inertial> -->
        <visual>
            <origin rpy="0 0 0" xyz="1 0 0" />
            <geometry>
                <mesh filename="package://iiwa_cam/src/meshes/space_assembly.stl" scale="1 1 1" />
            </geometry>
            <material name="White" />
        </visual>
        <collision>
            <origin rpy="0 0 0" xyz="1 0 0" />
            <geometry>
                <mesh filename="package://iiwa_cam/src/meshes/space_assembly.stl" scale="1 1 1" />
            </geometry>
            <material name="White" />
        </collision>
        <inertial>
            <mass value="0.1" />
            <origin xyz="0 0 0" rpy="0 0 0" />
            <inertia ixx="0.03" iyy="0.03" izz="0.03" ixy="0.0" ixz="0.0" iyz="0.0" />
        </inertial>
    </link>
    <!-- <origin xyz="1 0 0" rpy="0 0 0"/>
    </xacro:space_assembly> -->
</robot>

